<?xml	version="1.0"?>
<robot	name="capulus">
		<link	name="base_link">
				<visual>
						<geometry>
								<mesh filename="package://capulus/meshes/ChasisV1.6.dae" scale="1 1 1"	/>
						</geometry>
						<origin	rpy="0 0 0"	xyz="0 0 0.05"	/>
						<material	name="white">
								<color	rgba="0.5 0.5 0.5 1"	/>
						</material>
				</visual>
		</link>
		<link	name="left_side">
				<visual>
						<geometry>
								<mesh filename="package://capulus/meshes/SubensambleIzquierdo.dae" scale="1 1 1"	/>
						</geometry>
						<origin	rpy="1.57079632679 0 0"	xyz="0.055 0.47 0.022"	/>
						<material	name="black">
								<color	rgba="0.6 0.6 0.6 1"	/>
						</material>
				</visual>
		</link>
		<link	name="right_side">
				<visual>
						<geometry>
								<mesh filename="package://capulus/meshes/SubensambleDerecho.dae" scale="1 1 1"	/>
						</geometry>
						<origin	rpy="1.57079632679 0 0"	xyz="0.05 0.47 0.022"	/>
						<material	name="black"	/>
						<color	rgba="0.6 0.6 0.6 1"	/>
				</visual>
		</link>

		<joint	name="base_to_wheel1"	type="continuous">
				<parent	link="base_link"	/>
				<child	link="left_side"	/>
				<origin	rpy="0 0 0"   xyz="0 0 0"	/>
				<axis xyz="1 0 0"	/>
		</joint>
		<joint	name="base_to_wheel2"	type="continuous">
				<parent	link="base_link"	/>
				<child	link="right_side"	/>
				<origin	rpy="0 0 0"   xyz="0 0 0"	/>
				<axis xyz="1 0 0"	/>
		</joint>

</robot>
